Workbook

Sheet 1. Vendas
A1: REGISTRO DE VENDAS
A2: Uma linha por venda. Escolha o produto na listinha e o preço e o custo entram sozinhos (o preço pode ser trocado se você cobrou outro valor).
A3: AMARELO = você preenche | CINZA = calculado automaticamente (não digite)
A5: Para lançar uma venda nova use sempre a primeira linha vazia - as fórmulas já estão prontas até a linha 306. Colunas A a J você digita; K a N se calculam.
A6: Data | B6: Cliente | C6: Produto | D6: Qtd | E6: Preço unit. (R$) | F6: Desconto (R$) | G6: Status | H6: Pagamento | I6: Canal | J6: Observações | K6: Total (R$) | L6: Custo (R$) | M6: Lucro (R$) | N6: Mês (auto)
E7: =IF($C7="","",IFERROR(VLOOKUP($C7,'4. Produtos'!$A$6:$E$25,3,FALSE),0)) | K7: =IF(OR($C7="",$D7=""),"",$D7*$E7-N($F7)) | L7: =IF(OR($C7="",$D7=""),"",$D7*IFERROR(VLOOKUP($C7,'4. Produtos'!$A$6:$E$25,2,FALSE),0)) | M7: =IF(OR($C7="",$D7=""),"",$K7-$L7) | N7: =IF($A7="","",EOMONTH($A7,0))
E8: =IF($C8="","",IFERROR(VLOOKUP($C8,'4. Produtos'!$A$6:$E$25,3,FALSE),0)) | K8: =IF(OR($C8="",$D8=""),"",$D8*$E8-N($F8)) | L8: =IF(OR($C8="",$D8=""),"",$D8*IFERROR(VLOOKUP($C8,'4. Produtos'!$A$6:$E$25,2,FALSE),0)) | M8: =IF(OR($C8="",$D8=""),"",$K8-$L8) | N8: =IF($A8="","",EOMONTH($A8,0))
E9: =IF($C9="","",IFERROR(VLOOKUP($C9,'4. Produtos'!$A$6:$E$25,3,FALSE),0)) | K9: =IF(OR($C9="",$D9=""),"",$D9*$E9-N($F9)) | L9: =IF(OR($C9="",$D9=""),"",$D9*IFERROR(VLOOKUP($C9,'4. Produtos'!$A$6:$E$25,2,FALSE),0)) | M9: =IF(OR($C9="",$D9=""),"",$K9-$L9) | N9: =IF($A9="","",EOMONTH($A9,0))
E10: =IF($C10="","",IFERROR(VLOOKUP($C10,'4. Produtos'!$A$6:$E$25,3,FALSE),0)) | K10: =IF(OR($C10="",$D10=""),"",$D10*$E10-N($F10)) | L10: =IF(OR($C10="",$D10=""),"",$D10*IFERROR(VLOOKUP($C10,'4. Produtos'!$A$6:$E$25,2,FALSE),0)) | M10: =IF(OR($C10="",$D10=""),"",$K10-$L10) | N10: =IF($A10="","",EOMONTH($A10,0))
E11: =IF($C11="","",IFERROR(VLOOKUP($C11,'4. Produtos'!$A$6:$E$25,3,FALSE),0)) | K11: =IF(OR($C11="",$D11=""),"",$D11*$E11-N($F11)) | L11: =IF(OR($C11="",$D11=""),"",$D11*IFERROR(VLOOKUP($C11,'4. Produtos'!$A$6:$E$25,2,FALSE),0)) | M11: =IF(OR($C11="",$D11=""),"",$K11-$L11) | N11: =IF($A11="","",EOMONTH($A11,0))
E12: =IF($C12="","",IFERROR(VLOOKUP($C12,'4. Produtos'!$A$6:$E$25,3,FALSE),0)) | K12: =IF(OR($C12="",$D12=""),"",$D12*$E12-N($F12)) | L12: =IF(OR($C12="",$D12=""),"",$D12*IFERROR(VLOOKUP($C12,'4. Produtos'!$A$6:$E$25,2,FALSE),0)) | M12: =IF(OR($C12="",$D12=""),"",$K12-$L12) | N12: =IF($A12="","",EOMONTH($A12,0))
E13: =IF($C13="","",IFERROR(VLOOKUP($C13,'4. Produtos'!$A$6:$E$25,3,FALSE),0)) | K13: =IF(OR($C13="",$D13=""),"",$D13*$E13-N($F13)) | L13: =IF(OR($C13="",$D13=""),"",$D13*IFERROR(VLOOKUP($C13,'4. Produtos'!$A$6:$E$25,2,FALSE),0)) | M13: =IF(OR($C13="",$D13=""),"",$K13-$L13) | N13: =IF($A13="","",EOMONTH($A13,0))
E14: =IF($C14="","",IFERROR(VLOOKUP($C14,'4. Produtos'!$A$6:$E$25,3,FALSE),0)) | K14: =IF(OR($C14="",$D14=""),"",$D14*$E14-N($F14)) | L14: =IF(OR($C14="",$D14=""),"",$D14*IFERROR(VLOOKUP($C14,'4. Produtos'!$A$6:$E$25,2,FALSE),0)) | M14: =IF(OR($C14="",$D14=""),"",$K14-$L14) | N14: =IF($A14="","",EOMONTH($A14,0))
E15: =IF($C15="","",IFERROR(VLOOKUP($C15,'4. Produtos'!$A$6:$E$25,3,FALSE),0)) | K15: =IF(OR($C15="",$D15=""),"",$D15*$E15-N($F15)) | L15: =IF(OR($C15="",$D15=""),"",$D15*IFERROR(VLOOKUP($C15,'4. Produtos'!$A$6:$E$25,2,FALSE),0)) | M15: =IF(OR($C15="",$D15=""),"",$K15-$L15) | N15: =IF($A15="","",EOMONTH($A15,0))
E16: =IF($C16="","",IFERROR(VLOOKUP($C16,'4. Produtos'!$A$6:$E$25,3,FALSE),0)) | K16: =IF(OR($C16="",$D16=""),"",$D16*$E16-N($F16)) | L16: =IF(OR($C16="",$D16=""),"",$D16*IFERROR(VLOOKUP($C16,'4. Produtos'!$A$6:$E$25,2,FALSE),0)) | M16: =IF(OR($C16="",$D16=""),"",$K16-$L16) | N16: =IF($A16="","",EOMONTH($A16,0))
E17: =IF($C17="","",IFERROR(VLOOKUP($C17,'4. Produtos'!$A$6:$E$25,3,FALSE),0)) | K17: =IF(OR($C17="",$D17=""),"",$D17*$E17-N($F17)) | L17: =IF(OR($C17="",$D17=""),"",$D17*IFERROR(VLOOKUP($C17,'4. Produtos'!$A$6:$E$25,2,FALSE),0)) | M17: =IF(OR($C17="",$D17=""),"",$K17-$L17) | N17: =IF($A17="","",EOMONTH($A17,0))
E18: =IF($C18="","",IFERROR(VLOOKUP($C18,'4. Produtos'!$A$6:$E$25,3,FALSE),0)) | K18: =IF(OR($C18="",$D18=""),"",$D18*$E18-N($F18)) | L18: =IF(OR($C18="",$D18=""),"",$D18*IFERROR(VLOOKUP($C18,'4. Produtos'!$A$6:$E$25,2,FALSE),0)) | M18: =IF(OR($C18="",$D18=""),"",$K18-$L18) | N18: =IF($A18="","",EOMONTH($A18,0))
... E306: =IF($C306="","",IFERROR(VLOOKUP($C306,'4. Produtos'!$A$6:$E$25,3,FALSE),0)) | K306: =IF(OR($C306="",$D306=""),"",$D306*$E306-N($F306)) | L306: =IF(OR($C306="",$D306=""),"",$D306*IFERROR(VLOOKUP($C306,'4. Produtos'!$A$6:$E$25,2,FALSE),0)) | M306: =IF(OR($C306="",$D306=""),"",$K306-$L306) | N306: =IF($A306="","",EOMONTH($A306,0))

Sheet 2. Resumo
A1: RESUMO DAS VENDAS
A2: Esta aba só mostra resultados. Tudo vem da aba '1. Vendas' - não precisa digitar nada aqui.
A4: NÚMEROS GERAIS (todas as vendas lançadas)
A5: Vendas lançadas | B5: =COUNTA('1. Vendas'!$C$7:$C$306)
A6: Potes vendidos | B6: =SUM('1. Vendas'!$D$7:$D$306)
A7: FATURAMENTO | B7: =SUM('1. Vendas'!$K$7:$K$306)
A8: Custo dos produtos | B8: =SUM('1. Vendas'!$L$7:$L$306)
A9: LUCRO | B9: =SUM('1. Vendas'!$M$7:$M$306)
A10: Margem de lucro | B10: =IF($B$7=0,0,$B$9/$B$7)
A11: Ticket médio (por venda) | B11: =IF($B$5=0,0,$B$7/$B$5)
A13: DINHEIRO
A14: Já recebido (Pago) | B14: =SUMIF('1. Vendas'!$G$7:$G$306,"Pago",'1. Vendas'!$K$7:$K$306)
A15: A RECEBER (Pendente) | B15: =SUMIF('1. Vendas'!$G$7:$G$306,"Pendente",'1. Vendas'!$K$7:$K$306)
A17: POR PRODUTO
A18: Produto | B18: Potes | C18: Faturamento (R$) | D18: Lucro (R$)
A19: =IF('4. Produtos'!A6="","",'4. Produtos'!A6) | B19: =IF($A19="","",SUMIF('1. Vendas'!$C$7:$C$306,$A19,'1. Vendas'!$D$7:$D$306)) | C19: =IF($A19="","",SUMIF('1. Vendas'!$C$7:$C$306,$A19,'1. Vendas'!$K$7:$K$306)) | D19: =IF($A19="","",SUMIF('1. Vendas'!$C$7:$C$306,$A19,'1. Vendas'!$M$7:$M$306))
A20: =IF('4. Produtos'!A7="","",'4. Produtos'!A7) | B20: =IF($A20="","",SUMIF('1. Vendas'!$C$7:$C$306,$A20,'1. Vendas'!$D$7:$D$306)) | C20: =IF($A20="","",SUMIF('1. Vendas'!$C$7:$C$306,$A20,'1. Vendas'!$K$7:$K$306)) | D20: =IF($A20="","",SUMIF('1. Vendas'!$C$7:$C$306,$A20,'1. Vendas'!$M$7:$M$306))
A21: =IF('4. Produtos'!A8="","",'4. Produtos'!A8) | B21: =IF($A21="","",SUMIF('1. Vendas'!$C$7:$C$306,$A21,'1. Vendas'!$D$7:$D$306)) | C21: =IF($A21="","",SUMIF('1. Vendas'!$C$7:$C$306,$A21,'1. Vendas'!$K$7:$K$306)) | D21: =IF($A21="","",SUMIF('1. Vendas'!$C$7:$C$306,$A21,'1. Vendas'!$M$7:$M$306))
A22: =IF('4. Produtos'!A9="","",'4. Produtos'!A9) | B22: =IF($A22="","",SUMIF('1. Vendas'!$C$7:$C$306,$A22,'1. Vendas'!$D$7:$D$306)) | C22: =IF($A22="","",SUMIF('1. Vendas'!$C$7:$C$306,$A22,'1. Vendas'!$K$7:$K$306)) | D22: =IF($A22="","",SUMIF('1. Vendas'!$C$7:$C$306,$A22,'1. Vendas'!$M$7:$M$306))
A23: =IF('4. Produtos'!A10="","",'4. Produtos'!A10) | B23: =IF($A23="","",SUMIF('1. Vendas'!$C$7:$C$306,$A23,'1. Vendas'!$D$7:$D$306)) | C23: =IF($A23="","",SUMIF('1. Vendas'!$C$7:$C$306,$A23,'1. Vendas'!$K$7:$K$306)) | D23: =IF($A23="","",SUMIF('1. Vendas'!$C$7:$C$306,$A23,'1. Vendas'!$M$7:$M$306))
A24: =IF('4. Produtos'!A11="","",'4. Produtos'!A11) | B24: =IF($A24="","",SUMIF('1. Vendas'!$C$7:$C$306,$A24,'1. Vendas'!$D$7:$D$306)) | C24: =IF($A24="","",SUMIF('1. Vendas'!$C$7:$C$306,$A24,'1. Vendas'!$K$7:$K$306)) | D24: =IF($A24="","",SUMIF('1. Vendas'!$C$7:$C$306,$A24,'1. Vendas'!$M$7:$M$306))
A25: =IF('4. Produtos'!A12="","",'4. Produtos'!A12) | B25: =IF($A25="","",SUMIF('1. Vendas'!$C$7:$C$306,$A25,'1. Vendas'!$D$7:$D$306)) | C25: =IF($A25="","",SUMIF('1. Vendas'!$C$7:$C$306,$A25,'1. Vendas'!$K$7:$K$306)) | D25: =IF($A25="","",SUMIF('1. Vendas'!$C$7:$C$306,$A25,'1. Vendas'!$M$7:$M$306))
A26: =IF('4. Produtos'!A13="","",'4. Produtos'!A13) | B26: =IF($A26="","",SUMIF('1. Vendas'!$C$7:$C$306,$A26,'1. Vendas'!$D$7:$D$306)) | C26: =IF($A26="","",SUMIF('1. Vendas'!$C$7:$C$306,$A26,'1. Vendas'!$K$7:$K$306)) | D26: =IF($A26="","",SUMIF('1. Vendas'!$C$7:$C$306,$A26,'1. Vendas'!$M$7:$M$306))
A27: =IF('4. Produtos'!A14="","",'4. Produtos'!A14) | B27: =IF($A27="","",SUMIF('1. Vendas'!$C$7:$C$306,$A27,'1. Vendas'!$D$7:$D$306)) | C27: =IF($A27="","",SUMIF('1. Vendas'!$C$7:$C$306,$A27,'1. Vendas'!$K$7:$K$306)) | D27: =IF($A27="","",SUMIF('1. Vendas'!$C$7:$C$306,$A27,'1. Vendas'!$M$7:$M$306))
A28: =IF('4. Produtos'!A15="","",'4. Produtos'!A15) | B28: =IF($A28="","",SUMIF('1. Vendas'!$C$7:$C$306,$A28,'1. Vendas'!$D$7:$D$306)) | C28: =IF($A28="","",SUMIF('1. Vendas'!$C$7:$C$306,$A28,'1. Vendas'!$K$7:$K$306)) | D28: =IF($A28="","",SUMIF('1. Vendas'!$C$7:$C$306,$A28,'1. Vendas'!$M$7:$M$306))
A29: =IF('4. Produtos'!A16="","",'4. Produtos'!A16) | B29: =IF($A29="","",SUMIF('1. Vendas'!$C$7:$C$306,$A29,'1. Vendas'!$D$7:$D$306)) | C29: =IF($A29="","",SUMIF('1. Vendas'!$C$7:$C$306,$A29,'1. Vendas'!$K$7:$K$306)) | D29: =IF($A29="","",SUMIF('1. Vendas'!$C$7:$C$306,$A29,'1. Vendas'!$M$7:$M$306))
A30: =IF('4. Produtos'!A17="","",'4. Produtos'!A17) | B30: =IF($A30="","",SUMIF('1. Vendas'!$C$7:$C$306,$A30,'1. Vendas'!$D$7:$D$306)) | C30: =IF($A30="","",SUMIF('1. Vendas'!$C$7:$C$306,$A30,'1. Vendas'!$K$7:$K$306)) | D30: =IF($A30="","",SUMIF('1. Vendas'!$C$7:$C$306,$A30,'1. Vendas'!$M$7:$M$306))
... A38: =IF('4. Produtos'!A25="","",'4. Produtos'!A25) | B38: =IF($A38="","",SUMIF('1. Vendas'!$C$7:$C$306,$A38,'1. Vendas'!$D$7:$D$306)) | C38: =IF($A38="","",SUMIF('1. Vendas'!$C$7:$C$306,$A38,'1. Vendas'!$K$7:$K$306)) | D38: =IF($A38="","",SUMIF('1. Vendas'!$C$7:$C$306,$A38,'1. Vendas'!$M$7:$M$306))
A40: MÊS A MÊS
A41: Primeiro mês do quadro | B41: =EOMONTH(TODAY(),-11) | C41: <- edite se quiser começar em outro mês
A42: Mês | B42: Potes | C42: Faturamento (R$) | D42: Lucro (R$)
A43: =$B$41 | B43: =SUMIF('1. Vendas'!$N$7:$N$306,$A43,'1. Vendas'!$D$7:$D$306) | C43: =SUMIF('1. Vendas'!$N$7:$N$306,$A43,'1. Vendas'!$K$7:$K$306) | D43: =SUMIF('1. Vendas'!$N$7:$N$306,$A43,'1. Vendas'!$M$7:$M$306)
A44: =EOMONTH(A43,1) | B44: =SUMIF('1. Vendas'!$N$7:$N$306,$A44,'1. Vendas'!$D$7:$D$306) | C44: =SUMIF('1. Vendas'!$N$7:$N$306,$A44,'1. Vendas'!$K$7:$K$306) | D44: =SUMIF('1. Vendas'!$N$7:$N$306,$A44,'1. Vendas'!$M$7:$M$306)
A45: =EOMONTH(A44,1) | B45: =SUMIF('1. Vendas'!$N$7:$N$306,$A45,'1. Vendas'!$D$7:$D$306) | C45: =SUMIF('1. Vendas'!$N$7:$N$306,$A45,'1. Vendas'!$K$7:$K$306) | D45: =SUMIF('1. Vendas'!$N$7:$N$306,$A45,'1. Vendas'!$M$7:$M$306)
A46: =EOMONTH(A45,1) | B46: =SUMIF('1. Vendas'!$N$7:$N$306,$A46,'1. Vendas'!$D$7:$D$306) | C46: =SUMIF('1. Vendas'!$N$7:$N$306,$A46,'1. Vendas'!$K$7:$K$306) | D46: =SUMIF('1. Vendas'!$N$7:$N$306,$A46,'1. Vendas'!$M$7:$M$306)
A47: =EOMONTH(A46,1) | B47: =SUMIF('1. Vendas'!$N$7:$N$306,$A47,'1. Vendas'!$D$7:$D$306) | C47: =SUMIF('1. Vendas'!$N$7:$N$306,$A47,'1. Vendas'!$K$7:$K$306) | D47: =SUMIF('1. Vendas'!$N$7:$N$306,$A47,'1. Vendas'!$M$7:$M$306)
A48: =EOMONTH(A47,1) | B48: =SUMIF('1. Vendas'!$N$7:$N$306,$A48,'1. Vendas'!$D$7:$D$306) | C48: =SUMIF('1. Vendas'!$N$7:$N$306,$A48,'1. Vendas'!$K$7:$K$306) | D48: =SUMIF('1. Vendas'!$N$7:$N$306,$A48,'1. Vendas'!$M$7:$M$306)
A49: =EOMONTH(A48,1) | B49: =SUMIF('1. Vendas'!$N$7:$N$306,$A49,'1. Vendas'!$D$7:$D$306) | C49: =SUMIF('1. Vendas'!$N$7:$N$306,$A49,'1. Vendas'!$K$7:$K$306) | D49: =SUMIF('1. Vendas'!$N$7:$N$306,$A49,'1. Vendas'!$M$7:$M$306)
A50: =EOMONTH(A49,1) | B50: =SUMIF('1. Vendas'!$N$7:$N$306,$A50,'1. Vendas'!$D$7:$D$306) | C50: =SUMIF('1. Vendas'!$N$7:$N$306,$A50,'1. Vendas'!$K$7:$K$306) | D50: =SUMIF('1. Vendas'!$N$7:$N$306,$A50,'1. Vendas'!$M$7:$M$306)
A51: =EOMONTH(A50,1) | B51: =SUMIF('1. Vendas'!$N$7:$N$306,$A51,'1. Vendas'!$D$7:$D$306) | C51: =SUMIF('1. Vendas'!$N$7:$N$306,$A51,'1. Vendas'!$K$7:$K$306) | D51: =SUMIF('1. Vendas'!$N$7:$N$306,$A51,'1. Vendas'!$M$7:$M$306)
...

Sheet 3. Clientes
A1: CLIENTES
A2: Escreva o nome de cada cliente uma vez, do mesmo jeito que você escreve na aba de vendas. Os números aparecem sozinhos.
A5: Cliente | B5: Compras | C5: Potes | D5: Total comprado (R$) | E5: Lucro gerado (R$) | F5: Última compra | G5: Em aberto (R$)
B6: =IF($A6="","",COUNTIF('1. Vendas'!$B$7:$B$306,$A6)) | C6: =IF($A6="","",SUMIF('1. Vendas'!$B$7:$B$306,$A6,'1. Vendas'!$D$7:$D$306)) | D6: =IF($A6="","",SUMIF('1. Vendas'!$B$7:$B$306,$A6,'1. Vendas'!$K$7:$K$306)) | E6: =IF($A6="","",SUMIF('1. Vendas'!$B$7:$B$306,$A6,'1. Vendas'!$M$7:$M$306)) | F6: =IF($A6="","",IFERROR(MAXIFS('1. Vendas'!$A$7:$A$306,'1. Vendas'!$B$7:$B$306,$A6),"")) | G6: =IF($A6="","",SUMIFS('1. Vendas'!$K$7:$K$306,'1. Vendas'!$B$7:$B$306,$A6,'1. Vendas'!$G$7:$G$306,"Pendente"))
B7: =IF($A7="","",COUNTIF('1. Vendas'!$B$7:$B$306,$A7)) | C7: =IF($A7="","",SUMIF('1. Vendas'!$B$7:$B$306,$A7,'1. Vendas'!$D$7:$D$306)) | D7: =IF($A7="","",SUMIF('1. Vendas'!$B$7:$B$306,$A7,'1. Vendas'!$K$7:$K$306)) | E7: =IF($A7="","",SUMIF('1. Vendas'!$B$7:$B$306,$A7,'1. Vendas'!$M$7:$M$306)) | F7: =IF($A7="","",IFERROR(MAXIFS('1. Vendas'!$A$7:$A$306,'1. Vendas'!$B$7:$B$306,$A7),"")) | G7: =IF($A7="","",SUMIFS('1. Vendas'!$K$7:$K$306,'1. Vendas'!$B$7:$B$306,$A7,'1. Vendas'!$G$7:$G$306,"Pendente"))
B8: =IF($A8="","",COUNTIF('1. Vendas'!$B$7:$B$306,$A8)) | C8: =IF($A8="","",SUMIF('1. Vendas'!$B$7:$B$306,$A8,'1. Vendas'!$D$7:$D$306)) | D8: =IF($A8="","",SUMIF('1. Vendas'!$B$7:$B$306,$A8,'1. Vendas'!$K$7:$K$306)) | E8: =IF($A8="","",SUMIF('1. Vendas'!$B$7:$B$306,$A8,'1. Vendas'!$M$7:$M$306)) | F8: =IF($A8="","",IFERROR(MAXIFS('1. Vendas'!$A$7:$A$306,'1. Vendas'!$B$7:$B$306,$A8),"")) | G8: =IF($A8="","",SUMIFS('1. Vendas'!$K$7:$K$306,'1. Vendas'!$B$7:$B$306,$A8,'1. Vendas'!$G$7:$G$306,"Pendente"))
B9: =IF($A9="","",COUNTIF('1. Vendas'!$B$7:$B$306,$A9)) | C9: =IF($A9="","",SUMIF('1. Vendas'!$B$7:$B$306,$A9,'1. Vendas'!$D$7:$D$306)) | D9: =IF($A9="","",SUMIF('1. Vendas'!$B$7:$B$306,$A9,'1. Vendas'!$K$7:$K$306)) | E9: =IF($A9="","",SUMIF('1. Vendas'!$B$7:$B$306,$A9,'1. Vendas'!$M$7:$M$306)) | F9: =IF($A9="","",IFERROR(MAXIFS('1. Vendas'!$A$7:$A$306,'1. Vendas'!$B$7:$B$306,$A9),"")) | G9: =IF($A9="","",SUMIFS('1. Vendas'!$K$7:$K$306,'1. Vendas'!$B$7:$B$306,$A9,'1. Vendas'!$G$7:$G$306,"Pendente"))
B10: =IF($A10="","",COUNTIF('1. Vendas'!$B$7:$B$306,$A10)) | C10: =IF($A10="","",SUMIF('1. Vendas'!$B$7:$B$306,$A10,'1. Vendas'!$D$7:$D$306)) | D10: =IF($A10="","",SUMIF('1. Vendas'!$B$7:$B$306,$A10,'1. Vendas'!$K$7:$K$306)) | E10: =IF($A10="","",SUMIF('1. Vendas'!$B$7:$B$306,$A10,'1. Vendas'!$M$7:$M$306)) | F10: =IF($A10="","",IFERROR(MAXIFS('1. Vendas'!$A$7:$A$306,'1. Vendas'!$B$7:$B$306,$A10),"")) | G10: =IF($A10="","",SUMIFS('1. Vendas'!$K$7:$K$306,'1. Vendas'!$B$7:$B$306,$A10,'1. Vendas'!$G$7:$G$306,"Pendente"))
B11: =IF($A11="","",COUNTIF('1. Vendas'!$B$7:$B$306,$A11)) | C11: =IF($A11="","",SUMIF('1. Vendas'!$B$7:$B$306,$A11,'1. Vendas'!$D$7:$D$306)) | D11: =IF($A11="","",SUMIF('1. Vendas'!$B$7:$B$306,$A11,'1. Vendas'!$K$7:$K$306)) | E11: =IF($A11="","",SUMIF('1. Vendas'!$B$7:$B$306,$A11,'1. Vendas'!$M$7:$M$306)) | F11: =IF($A11="","",IFERROR(MAXIFS('1. Vendas'!$A$7:$A$306,'1. Vendas'!$B$7:$B$306,$A11),"")) | G11: =IF($A11="","",SUMIFS('1. Vendas'!$K$7:$K$306,'1. Vendas'!$B$7:$B$306,$A11,'1. Vendas'!$G$7:$G$306,"Pendente"))
B12: =IF($A12="","",COUNTIF('1. Vendas'!$B$7:$B$306,$A12)) | C12: =IF($A12="","",SUMIF('1. Vendas'!$B$7:$B$306,$A12,'1. Vendas'!$D$7:$D$306)) | D12: =IF($A12="","",SUMIF('1. Vendas'!$B$7:$B$306,$A12,'1. Vendas'!$K$7:$K$306)) | E12: =IF($A12="","",SUMIF('1. Vendas'!$B$7:$B$306,$A12,'1. Vendas'!$M$7:$M$306)) | F12: =IF($A12="","",IFERROR(MAXIFS('1. Vendas'!$A$7:$A$306,'1. Vendas'!$B$7:$B$306,$A12),"")) | G12: =IF($A12="","",SUMIFS('1. Vendas'!$K$7:$K$306,'1. Vendas'!$B$7:$B$306,$A12,'1. Vendas'!$G$7:$G$306,"Pendente"))
B13: =IF($A13="","",COUNTIF('1. Vendas'!$B$7:$B$306,$A13)) | C13: =IF($A13="","",SUMIF('1. Vendas'!$B$7:$B$306,$A13,'1. Vendas'!$D$7:$D$306)) | D13: =IF($A13="","",SUMIF('1. Vendas'!$B$7:$B$306,$A13,'1. Vendas'!$K$7:$K$306)) | E13: =IF($A13="","",SUMIF('1. Vendas'!$B$7:$B$306,$A13,'1. Vendas'!$M$7:$M$306)) | F13: =IF($A13="","",IFERROR(MAXIFS('1. Vendas'!$A$7:$A$306,'1. Vendas'!$B$7:$B$306,$A13),"")) | G13: =IF($A13="","",SUMIFS('1. Vendas'!$K$7:$K$306,'1. Vendas'!$B$7:$B$306,$A13,'1. Vendas'!$G$7:$G$306,"Pendente"))
B14: =IF($A14="","",COUNTIF('1. Vendas'!$B$7:$B$306,$A14)) | C14: =IF($A14="","",SUMIF('1. Vendas'!$B$7:$B$306,$A14,'1. Vendas'!$D$7:$D$306)) | D14: =IF($A14="","",SUMIF('1. Vendas'!$B$7:$B$306,$A14,'1. Vendas'!$K$7:$K$306)) | E14: =IF($A14="","",SUMIF('1. Vendas'!$B$7:$B$306,$A14,'1. Vendas'!$M$7:$M$306)) | F14: =IF($A14="","",IFERROR(MAXIFS('1. Vendas'!$A$7:$A$306,'1. Vendas'!$B$7:$B$306,$A14),"")) | G14: =IF($A14="","",SUMIFS('1. Vendas'!$K$7:$K$306,'1. Vendas'!$B$7:$B$306,$A14,'1. Vendas'!$G$7:$G$306,"Pendente"))
B15: =IF($A15="","",COUNTIF('1. Vendas'!$B$7:$B$306,$A15)) | C15: =IF($A15="","",SUMIF('1. Vendas'!$B$7:$B$306,$A15,'1. Vendas'!$D$7:$D$306)) | D15: =IF($A15="","",SUMIF('1. Vendas'!$B$7:$B$306,$A15,'1. Vendas'!$K$7:$K$306)) | E15: =IF($A15="","",SUMIF('1. Vendas'!$B$7:$B$306,$A15,'1. Vendas'!$M$7:$M$306)) | F15: =IF($A15="","",IFERROR(MAXIFS('1. Vendas'!$A$7:$A$306,'1. Vendas'!$B$7:$B$306,$A15),"")) | G15: =IF($A15="","",SUMIFS('1. Vendas'!$K$7:$K$306,'1. Vendas'!$B$7:$B$306,$A15,'1. Vendas'!$G$7:$G$306,"Pendente"))
B16: =IF($A16="","",COUNTIF('1. Vendas'!$B$7:$B$306,$A16)) | C16: =IF($A16="","",SUMIF('1. Vendas'!$B$7:$B$306,$A16,'1. Vendas'!$D$7:$D$306)) | D16: =IF($A16="","",SUMIF('1. Vendas'!$B$7:$B$306,$A16,'1. Vendas'!$K$7:$K$306)) | E16: =IF($A16="","",SUMIF('1. Vendas'!$B$7:$B$306,$A16,'1. Vendas'!$M$7:$M$306)) | F16: =IF($A16="","",IFERROR(MAXIFS('1. Vendas'!$A$7:$A$306,'1. Vendas'!$B$7:$B$306,$A16),"")) | G16: =IF($A16="","",SUMIFS('1. Vendas'!$K$7:$K$306,'1. Vendas'!$B$7:$B$306,$A16,'1. Vendas'!$G$7:$G$306,"Pendente"))
B17: =IF($A17="","",COUNTIF('1. Vendas'!$B$7:$B$306,$A17)) | C17: =IF($A17="","",SUMIF('1. Vendas'!$B$7:$B$306,$A17,'1. Vendas'!$D$7:$D$306)) | D17: =IF($A17="","",SUMIF('1. Vendas'!$B$7:$B$306,$A17,'1. Vendas'!$K$7:$K$306)) | E17: =IF($A17="","",SUMIF('1. Vendas'!$B$7:$B$306,$A17,'1. Vendas'!$M$7:$M$306)) | F17: =IF($A17="","",IFERROR(MAXIFS('1. Vendas'!$A$7:$A$306,'1. Vendas'!$B$7:$B$306,$A17),"")) | G17: =IF($A17="","",SUMIFS('1. Vendas'!$K$7:$K$306,'1. Vendas'!$B$7:$B$306,$A17,'1. Vendas'!$G$7:$G$306,"Pendente"))
... B55: =IF($A55="","",COUNTIF('1. Vendas'!$B$7:$B$306,$A55)) | C55: =IF($A55="","",SUMIF('1. Vendas'!$B$7:$B$306,$A55,'1. Vendas'!$D$7:$D$306)) | D55: =IF($A55="","",SUMIF('1. Vendas'!$B$7:$B$306,$A55,'1. Vendas'!$K$7:$K$306)) | E55: =IF($A55="","",SUMIF('1. Vendas'!$B$7:$B$306,$A55,'1. Vendas'!$M$7:$M$306)) | F55: =IF($A55="","",IFERROR(MAXIFS('1. Vendas'!$A$7:$A$306,'1. Vendas'!$B$7:$B$306,$A55),"")) | G55: =IF($A55="","",SUMIFS('1. Vendas'!$K$7:$K$306,'1. Vendas'!$B$7:$B$306,$A55,'1. Vendas'!$G$7:$G$306,"Pendente"))
A57: Escreva o nome sempre igual nas duas abas - 'Ana' e 'ana maria' contam como clientes diferentes.

Sheet 4. Produtos
A1: PRODUTOS À VENDA
A2: O custo por pote vem da planilha de custos (aba Resumo). Se o preço dos insumos mudar lá, atualize aqui.
A3: AMARELO = você edita | CINZA = calculado automaticamente
A5: Produto | B5: Custo por pote (R$) | C5: Preço de venda (R$) | D5: Lucro por pote (R$) | E5: Margem
A6: Café | B6: 7.26 | C6: 25 | D6: =IF($A6="","",$C6-$B6) | E6: =IF(OR($A6="",$C6=0),"",$D6/$C6)
A7: Cappuccino | B7: 9.01 | C7: 25 | D7: =IF($A7="","",$C7-$B7) | E7: =IF(OR($A7="",$C7=0),"",$D7/$C7)
D8: =IF($A8="","",$C8-$B8) | E8: =IF(OR($A8="",$C8=0),"",$D8/$C8)
D9: =IF($A9="","",$C9-$B9) | E9: =IF(OR($A9="",$C9=0),"",$D9/$C9)
D10: =IF($A10="","",$C10-$B10) | E10: =IF(OR($A10="",$C10=0),"",$D10/$C10)
D11: =IF($A11="","",$C11-$B11) | E11: =IF(OR($A11="",$C11=0),"",$D11/$C11)
D12: =IF($A12="","",$C12-$B12) | E12: =IF(OR($A12="",$C12=0),"",$D12/$C12)
D13: =IF($A13="","",$C13-$B13) | E13: =IF(OR($A13="",$C13=0),"",$D13/$C13)
D14: =IF($A14="","",$C14-$B14) | E14: =IF(OR($A14="",$C14=0),"",$D14/$C14)
D15: =IF($A15="","",$C15-$B15) | E15: =IF(OR($A15="",$C15=0),"",$D15/$C15)
D16: =IF($A16="","",$C16-$B16) | E16: =IF(OR($A16="",$C16=0),"",$D16/$C16)
D17: =IF($A17="","",$C17-$B17) | E17: =IF(OR($A17="",$C17=0),"",$D17/$C17)
D18: =IF($A18="","",$C18-$B18) | E18: =IF(OR($A18="",$C18=0),"",$D18/$C18)
D19: =IF($A19="","",$C19-$B19) | E19: =IF(OR($A19="",$C19=0),"",$D19/$C19)
... D25: =IF($A25="","",$C25-$B25) | E25: =IF(OR($A25="",$C25=0),"",$D25/$C25)
A27: Pode cadastrar produtos novos nas linhas vazias (kit com 2 potes, tamanho menor, edição de Natal...) - eles aparecem na listinha da aba de vendas.

Sheet 5. Listas
A1: OPÇÕES DAS LISTINHAS
A2: Status | B2: Pagamento | C2: Canal
A3: Pago | B3: Pix | C3: WhatsApp
A4: Pendente | B4: Dinheiro | C4: Instagram
B5: Cartão de débito | C5: Feira
B6: Cartão de crédito | C6: Indicação
B7: Transferência | C7: Presente
B8: Outro | C8: Outro
A11: Pode trocar ou acrescentar opções aqui - elas aparecem nas listinhas da aba de vendas.
